Workbook

Sheet User Guide
A1: How to set up a Project
A2: *If you need any assistanse contact Clay Scheller
A3: 1. Create a copy of the template to your desktop and rename it to the project's name… DO NOT MODIFY THE TEMPLATE
A4: 2. On the "Project Data" tab, enter your Project Name and Address in the highlighted boxes
A5: 2b. As you work through project takeoffs, be sure to get the required SF for the listed items on the "Project Data" sheet
A6: 2c. At the bottom of the "Project Data" sheet, input Contingency, insurance, Bond, and Fee % (this will automatically calculate on the "OVERALL" sheet)
A7: 3. Go through separate division tabs 02-48 (NOT THE OVERALL SHEET)
A8: 3.b Division tabs have been prepopulated for the most used CSI codes. If you need other codes, Un Filter the sheet to see all codes. When you need to enter project scope specific information, you can overwrite any unused CSI codes. DO NOT DELETE OR ADD ANY LINES!
A9: 3C. Insert a "1" in column A in the cell next to each CSI code you will be using for this project
A10: If you want to see a CSI code broken out on a division tab, but not on the overall sheet, put a "2" in column A
A11: 4. On the OVERALL tab, use the filter in the top left and select only "1"
A12: 5. After setting up the project reference the "Entering Bids and Selecting Subcontractors" instructions below
... A24: 5a. If you are bid leveling with multiple vendors and need to uses more than one vendor, you must populate the information into one vendor column. Example - you are using vendor 1 for structural steel and vendor 2 for Misc metals. See below.
A25: #VALUE!
A26: 6. Once you have selected a bid for all of the divisions you are using in the project, go to the OVERALL tab and refresh the filter.
A27: To refresh the filter click on the filter icon on the filter cell line 8 and click "OK"
A28: 7. Check to make sure you have a number in each division you will be using. Hide the rows of divisions that you will not be using.
A29: 8. GC/GR's - Enter the Project Start Date and the Project Substantial Completion Date. The duration will auto populate.
A30: 9. Adjust your staffing and GR's accordingly. (there are formulas in some of the cells, you can adjust them as needed)
A31: 10. Once GC's and GR's have been entered, make sure there are no values beyond the completion date. All totals will auto calculate and populate the OVERAll sheet.
A32: 11. You can hide any NA months once you have finised GC's.

Sheet OVERALL
A8: Filter
A9: 1 | B9: PROJECT: | K9: DATE:
A10: 1 | B10: ='Project Data'!B4 -> Josephine Apartments (3rd Ave.) | G10: ='Project Data'!B5 -> 3rd Avenue | K10: =TODAY() -> 46090
A11: 1 | B11: ITEM | D11: GMP 1.23.26 | E11: Cost Per GSF | F11: Review Adjustments | G11: Current Budget Date | H11: Cost Per GSF | I11: ERROR | J11: Difference | K11: Notes
B12: INITIAL SF BUDGET | G12: =SUM(G13:G16) -> 0
D13: Copy and Paste VALUES ONLY! | F13: Copy and Paste VALUES ONLY!
A17: 1 | B17: Div. 02 - General Requirements | D17: =D28+D29+D43+D47 -> 121952 | E17: =D17/'Project Data'!$D$22 -> 1.3627292 | F17: 0 | G17: {=_xlfn.IFNA(_xlfn.IFS('02-Existing Conditions'!F9="*",'02-Existing Conditions'!E9,'02-Existing Conditions'!H9="*",'02-Existing Conditions'!G9,'02-Existing Conditions'!J9="*",'02-Existing Conditions'!I9,'02-Existing Conditions'!L9="*",'02-Existing Conditions'!K9,'02-Existing Conditions'!N9="*",'02-Existing Conditions'!M9,'02-Existing Conditions'!P9="*",'02-Existing Conditions'!O9,'02-Existing Conditions'!R9="*",'02-Existing Conditions'!Q9,'02-Existing Conditions'!T9="*",'02-Existing Conditions'!S9,'02-Existing Conditions'!V9="*",'02-Existing Conditions'!U9),"")} -> 0 | H17: =G17/'Project Data'!$D$22 -> #VALUE! | I17: ='02-Existing Conditions'!XFC9 | J17: =IFERROR(G17-F17, "--") -> --
A18: ='02-Existing Conditions'!A11 -> 0 | B18: ='02-Existing Conditions'!B11 -> 02 00 00 Existing Conditions | D18: {=_xlfn.IFNA(_xlfn.IFS('02-Existing Conditions'!D11="*",'02-Existing Conditions'!C11,'02-Existing Conditions'!F11="*",'02-Existing Conditions'!E11,'02-Existing Conditions'!H11="*",'02-Existing Conditions'!G11,'02-Existing Conditions'!J11="*",'02-Existing Conditions'!I11,'02-Existing Conditions'!L11="*",'02-Existing Conditions'!K11,'02-Existing Conditions'!N11="*",'02-Existing Conditions'!M11,'02-Existing Conditions'!P11="*",'02-Existing Conditions'!O11,'02-Existing Conditions'!R11="*",'02-Existing Conditions'!Q11,'02-Existing Conditions'!T11="*",'02-Existing Conditions'!S11),"")} | E18: =D18/'Project Data'!$D$22 -> 0 | G18: {=_xlfn.IFNA(_xlfn.IFS('02-Existing Conditions'!F11="*",'02-Existing Conditions'!E11,'02-Existing Conditions'!H11="*",'02-Existing Conditions'!G11,'02-Existing Conditions'!J11="*",'02-Existing Conditions'!I11,'02-Existing Conditions'!L11="*",'02-Existing Conditions'!K11,'02-Existing Conditions'!N11="*",'02-Existing Conditions'!M11,'02-Existing Conditions'!P11="*",'02-Existing Conditions'!O11,'02-Existing Conditions'!R11="*",'02-Existing Conditions'!Q11,'02-Existing Conditions'!T11="*",'02-Existing Conditions'!S11,'02-Existing Conditions'!V11="*",'02-Existing Conditions'!U11),"")} | H18: =G18/'Project Data'!$D$22 -> #VALUE!
A19: ='02-Existing Conditions'!A12 -> 0 | B19: ='02-Existing Conditions'!B12 -> 02 03 00 Conservation Treatment for Existing Period Conditions | D19: {=_xlfn.IFNA(_xlfn.IFS('02-Existing Conditions'!D12="*",'02-Existing Conditions'!C12,'02-Existing Conditions'!F12="*",'02-Existing Conditions'!E12,'02-Existing Conditions'!H12="*",'02-Existing Conditions'!G12,'02-Existing Conditions'!J12="*",'02-Existing Conditions'!I12,'02-Existing Conditions'!L12="*",'02-Existing Conditions'!K12,'02-Existing Conditions'!N12="*",'02-Existing Conditions'!M12,'02-Existing Conditions'!P12="*",'02-Existing Conditions'!O12,'02-Existing Conditions'!R12="*",'02-Existing Conditions'!Q12,'02-Existing Conditions'!T12="*",'02-Existing Conditions'!S12),"")} -> 0 | E19: =D19/'Project Data'!$D$22 -> 0 | F19: 0 | G19: {=_xlfn.IFNA(_xlfn.IFS('02-Existing Conditions'!F12="*",'02-Existing Conditions'!E12,'02-Existing Conditions'!H12="*",'02-Existing Conditions'!G12,'02-Existing Conditions'!J12="*",'02-Existing Conditions'!I12,'02-Existing Conditions'!L12="*",'02-Existing Conditions'!K12,'02-Existing Conditions'!N12="*",'02-Existing Conditions'!M12,'02-Existing Conditions'!P12="*",'02-Existing Conditions'!O12,'02-Existing Conditions'!R12="*",'02-Existing Conditions'!Q12,'02-Existing Conditions'!T12="*",'02-Existing Conditions'!S12,'02-Existing Conditions'!V12="*",'02-Existing Conditions'!U12),"")} -> 0 | H19: =G19/'Project Data'!$D$22 -> #VALUE!
A20: ='02-Existing Conditions'!A13 -> 0 | B20: ='02-Existing Conditions'!B13 -> 02 05 00 Common Work Results for Existing Conditions | D20: {=_xlfn.IFNA(_xlfn.IFS('02-Existing Conditions'!D13="*",'02-Existing Conditions'!C13,'02-Existing Conditions'!F13="*",'02-Existing Conditions'!E13,'02-Existing Conditions'!H13="*",'02-Existing Conditions'!G13,'02-Existing Conditions'!J13="*",'02-Existing Conditions'!I13,'02-Existing Conditions'!L13="*",'02-Existing Conditions'!K13,'02-Existing Conditions'!N13="*",'02-Existing Conditions'!M13,'02-Existing Conditions'!P13="*",'02-Existing Conditions'!O13,'02-Existing Conditions'!R13="*",'02-Existing Conditions'!Q13,'02-Existing Conditions'!T13="*",'02-Existing Conditions'!S13),"")} -> 0 | E20: =D20/'Project Data'!$D$22 -> 0 | F20: 0 | G20: {=_xlfn.IFNA(_xlfn.IFS('02-Existing Conditions'!F13="*",'02-Existing Conditions'!E13,'02-Existing Conditions'!H13="*",'02-Existing Conditions'!G13,'02-Existing Conditions'!J13="*",'02-Existing Conditions'!I13,'02-Existing Conditions'!L13="*",'02-Existing Conditions'!K13,'02-Existing Conditions'!N13="*",'02-Existing Conditions'!M13,'02-Existing Conditions'!P13="*",'02-Existing Conditions'!O13,'02-Existing Conditions'!R13="*",'02-Existing Conditions'!Q13,'02-Existing Conditions'!T13="*",'02-Existing Conditions'!S13,'02-Existing Conditions'!V13="*",'02-Existing Conditions'!U13),"")} -> 0 | H20: =G20/'Project Data'!$D$22 -> #VALUE!
A21: ='02-Existing Conditions'!A14 -> 0 | B21: ='02-Existing Conditions'!B14 -> 02 06 00 Schedules for Existing Conditions | D21: {=_xlfn.IFNA(_xlfn.IFS('02-Existing Conditions'!D14="*",'02-Existing Conditions'!C14,'02-Existing Conditions'!F14="*",'02-Existing Conditions'!E14,'02-Existing Conditions'!H14="*",'02-Existing Conditions'!G14,'02-Existing Conditions'!J14="*",'02-Existing Conditions'!I14,'02-Existing Conditions'!L14="*",'02-Existing Conditions'!K14,'02-Existing Conditions'!N14="*",'02-Existing Conditions'!M14,'02-Existing Conditions'!P14="*",'02-Existing Conditions'!O14,'02-Existing Conditions'!R14="*",'02-Existing Conditions'!Q14,'02-Existing Conditions'!T14="*",'02-Existing Conditions'!S14),"")} -> 0 | E21: =D21/'Project Data'!$D$22 -> 0 | F21: 0 | G21: {=_xlfn.IFNA(_xlfn.IFS('02-Existing Conditions'!F14="*",'02-Existing Conditions'!E14,'02-Existing Conditions'!H14="*",'02-Existing Conditions'!G14,'02-Existing Conditions'!J14="*",'02-Existing Conditions'!I14,'02-Existing Conditions'!L14="*",'02-Existing Conditions'!K14,'02-Existing Conditions'!N14="*",'02-Existing Conditions'!M14,'02-Existing Conditions'!P14="*",'02-Existing Conditions'!O14,'02-Existing Conditions'!R14="*",'02-Existing Conditions'!Q14,'02-Existing Conditions'!T14="*",'02-Existing Conditions'!S14,'02-Existing Conditions'!V14="*",'02-Existing Conditions'!U14),"")} -> 0 | H21: =G21/'Project Data'!$D$22 -> #VALUE!
A22: ='02-Existing Conditions'!A15 -> 0 | B22: ='02-Existing Conditions'!B15 -> 02 06 30 Schedules for Subsurface Investigations | D22: {=_xlfn.IFNA(_xlfn.IFS('02-Existing Conditions'!D15="*",'02-Existing Conditions'!C15,'02-Existing Conditions'!F15="*",'02-Existing Conditions'!E15,'02-Existing Conditions'!H15="*",'02-Existing Conditions'!G15,'02-Existing Conditions'!J15="*",'02-Existing Conditions'!I15,'02-Existing Conditions'!L15="*",'02-Existing Conditions'!K15,'02-Existing Conditions'!N15="*",'02-Existing Conditions'!M15,'02-Existing Conditions'!P15="*",'02-Existing Conditions'!O15,'02-Existing Conditions'!R15="*",'02-Existing Conditions'!Q15,'02-Existing Conditions'!T15="*",'02-Existing Conditions'!S15),"")} -> 0 | E22: =D22/'Project Data'!$D$22 -> 0 | F22: 0 | G22: {=_xlfn.IFNA(_xlfn.IFS('02-Existing Conditions'!F15="*",'02-Existing Conditions'!E15,'02-Existing Conditions'!H15="*",'02-Existing Conditions'!G15,'02-Existing Conditions'!J15="*",'02-Existing Conditions'!I15,'02-Existing Conditions'!L15="*",'02-Existing Conditions'!K15,'02-Existing Conditions'!N15="*",'02-Existing Conditions'!M15,'02-Existing Conditions'!P15="*",'02-Existing Conditions'!O15,'02-Existing Conditions'!R15="*",'02-Existing Conditions'!Q15,'02-Existing Conditions'!T15="*",'02-Existing Conditions'!S15,'02-Existing Conditions'!V15="*",'02-Existing Conditions'!U15),"")} -> 0 | H22: =G22/'Project Data'!$D$22 -> #VALUE!
A23: ='02-Existing Conditions'!A16 -> 0 | B23: ='02-Existing Conditions'!B16 -> 02 06 30.13 Boring or Test Pit Log Schedule | D23: {=_xlfn.IFNA(_xlfn.IFS('02-Existing Conditions'!D16="*",'02-Existing Conditions'!C16,'02-Existing Conditions'!F16="*",'02-Existing Conditions'!E16,'02-Existing Conditions'!H16="*",'02-Existing Conditions'!G16,'02-Existing Conditions'!J16="*",'02-Existing Conditions'!I16,'02-Existing Conditions'!L16="*",'02-Existing Conditions'!K16,'02-Existing Conditions'!N16="*",'02-Existing Conditions'!M16,'02-Existing Conditions'!P16="*",'02-Existing Conditions'!O16,'02-Existing Conditions'!R16="*",'02-Existing Conditions'!Q16,'02-Existing Conditions'!T16="*",'02-Existing Conditions'!S16),"")} -> 0 | E23: =D23/'Project Data'!$D$22 -> 0 | F23: 0 | G23: {=_xlfn.IFNA(_xlfn.IFS('02-Existing Conditions'!F16="*",'02-Existing Conditions'!E16,'02-Existing Conditions'!H16="*",'02-Existing Conditions'!G16,'02-Existing Conditions'!J16="*",'02-Existing Conditions'!I16,'02-Existing Conditions'!L16="*",'02-Existing Conditions'!K16,'02-Existing Conditions'!N16="*",'02-Existing Conditions'!M16,'02-Existing Conditions'!P16="*",'02-Existing Conditions'!O16,'02-Existing Conditions'!R16="*",'02-Existing Conditions'!Q16,'02-Existing Conditions'!T16="*",'02-Existing Conditions'!S16,'02-Existing Conditions'!V16="*",'02-Existing Conditions'!U16),"")} -> 0 | H23: =G23/'Project Data'!$D$22 -> #VALUE!
A24: ='02-Existing Conditions'!A17 -> 0 | B24: ='02-Existing Conditions'!B17 -> 02 06 50 Schedules for Site Remediation | D24: {=_xlfn.IFNA(_xlfn.IFS('02-Existing Conditions'!D17="*",'02-Existing Conditions'!C17,'02-Existing Conditions'!F17="*",'02-Existing Conditions'!E17,'02-Existing Conditions'!H17="*",'02-Existing Conditions'!G17,'02-Existing Conditions'!J17="*",'02-Existing Conditions'!I17,'02-Existing Conditions'!L17="*",'02-Existing Conditions'!K17,'02-Existing Conditions'!N17="*",'02-Existing Conditions'!M17,'02-Existing Conditions'!P17="*",'02-Existing Conditions'!O17,'02-Existing Conditions'!R17="*",'02-Existing Conditions'!Q17,'02-Existing Conditions'!T17="*",'02-Existing Conditions'!S17),"")} -> 0 | E24: =D24/'Project Data'!$D$22 -> 0 | F24: 0 | G24: {=_xlfn.IFNA(_xlfn.IFS('02-Existing Conditions'!F17="*",'02-Existing Conditions'!E17,'02-Existing Conditions'!H17="*",'02-Existing Conditions'!G17,'02-Existing Conditions'!J17="*",'02-Existing Conditions'!I17,'02-Existing Conditions'!L17="*",'02-Existing Conditions'!K17,'02-Existing Conditions'!N17="*",'02-Existing Conditions'!M17,'02-Existing Conditions'!P17="*",'02-Existing Conditions'!O17,'02-Existing Conditions'!R17="*",'02-Existing Conditions'!Q17,'02-Existing Conditions'!T17="*",'02-Existing Conditions'!S17,'02-Existing Conditions'!V17="*",'02-Existing Conditions'!U17),"")} -> 0 | H24: =G24/'Project Data'!$D$22 -> #VALUE!
A25: ='02-Existing Conditions'!A18 -> 0 | B25: ='02-Existing Conditions'!B18 -> 02 06 65 Schedules for Underground Storage Tank Removal | D25: {=_xlfn.IFNA(_xlfn.IFS('02-Existing Conditions'!D18="*",'02-Existing Conditions'!C18,'02-Existing Conditions'!F18="*",'02-Existing Conditions'!E18,'02-Existing Conditions'!H18="*",'02-Existing Conditions'!G18,'02-Existing Conditions'!J18="*",'02-Existing Conditions'!I18,'02-Existing Conditions'!L18="*",'02-Existing Conditions'!K18,'02-Existing Conditions'!N18="*",'02-Existing Conditions'!M18,'02-Existing Conditions'!P18="*",'02-Existing Conditions'!O18,'02-Existing Conditions'!R18="*",'02-Existing Conditions'!Q18,'02-Existing Conditions'!T18="*",'02-Existing Conditions'!S18),"")} -> 0 | E25: =D25/'Project Data'!$D$22 -> 0 | F25: 0 | G25: {=_xlfn.IFNA(_xlfn.IFS('02-Existing Conditions'!F18="*",'02-Existing Conditions'!E18,'02-Existing Conditions'!H18="*",'02-Existing Conditions'!G18,'02-Existing Conditions'!J18="*",'02-Existing Conditions'!I18,'02-Existing Conditions'!L18="*",'02-Existing Conditions'!K18,'02-Existing Conditions'!N18="*",'02-Existing Conditions'!M18,'02-Existing Conditions'!P18="*",'02-Existing Conditions'!O18,'02-Existing Conditions'!R18="*",'02-Existing Conditions'!Q18,'02-Existing Conditions'!T18="*",'02-Existing Conditions'!S18,'02-Existing Conditions'!V18="*",'02-Existing Conditions'!U18),"")} -> 0 | H25: =G25/'Project Data'!$D$22 -> #VALUE!
A26: ='02-Existing Conditions'!A19 -> 0 | B26: ='02-Existing Conditions'!B19 -> 02 06 80 Schedules for Facility Remediation | D26: {=_xlfn.IFNA(_xlfn.IFS('02-Existing Conditions'!D19="*",'02-Existing Conditions'!C19,'02-Existing Conditions'!F19="*",'02-Existing Conditions'!E19,'02-Existing Conditions'!H19="*",'02-Existing Conditions'!G19,'02-Existing Conditions'!J19="*",'02-Existing Conditions'!I19,'02-Existing Conditions'!L19="*",'02-Existing Conditions'!K19,'02-Existing Conditions'!N19="*",'02-Existing Conditions'!M19,'02-Existing Conditions'!P19="*",'02-Existing Conditions'!O19,'02-Existing Conditions'!R19="*",'02-Existing Conditions'!Q19,'02-Existing Conditions'!T19="*",'02-Existing Conditions'!S19),"")} -> 0 | E26: =D26/'Project Data'!$D$22 -> 0 | F26: 0 | G26: {=_xlfn.IFNA(_xlfn.IFS('02-Existing Conditions'!F19="*",'02-Existing Conditions'!E19,'02-Existing Conditions'!H19="*",'02-Existing Conditions'!G19,'02-Existing Conditions'!J19="*",'02-Existing Conditions'!I19,'02-Existing Conditions'!L19="*",'02-Existing Conditions'!K19,'02-Existing Conditions'!N19="*",'02-Existing Conditions'!M19,'02-Existing Conditions'!P19="*",'02-Existing Conditions'!O19,'02-Existing Conditions'!R19="*",'02-Existing Conditions'!Q19,'02-Existing Conditions'!T19="*",'02-Existing Conditions'!S19,'02-Existing Conditions'!V19="*",'02-Existing Conditions'!U19),"")} -> 0 | H26: =G26/'Project Data'!$D$22 -> #VALUE!
A27: ='02-Existing Conditions'!A20 -> 0 | B27: ='02-Existing Conditions'!B20 -> 02 06 86 Schedules for Hazardous Waste Drum Handling | D27: {=_xlfn.IFNA(_xlfn.IFS('02-Existing Conditions'!D20="*",'02-Existing Conditions'!C20,'02-Existing Conditions'!F20="*",'02-Existing Conditions'!E20,'02-Existing Conditions'!H20="*",'02-Existing Conditions'!G20,'02-Existing Conditions'!J20="*",'02-Existing Conditions'!I20,'02-Existing Conditions'!L20="*",'02-Existing Conditions'!K20,'02-Existing Conditions'!N20="*",'02-Existing Conditions'!M20,'02-Existing Conditions'!P20="*",'02-Existing Conditions'!O20,'02-Existing Conditions'!R20="*",'02-Existing Conditions'!Q20,'02-Existing Conditions'!T20="*",'02-Existing Conditions'!S20),"")} -> 0 | E27: =D27/'Project Data'!$D$22 -> 0 | F27: 0 | G27: {=_xlfn.IFNA(_xlfn.IFS('02-Existing Conditions'!F20="*",'02-Existing Conditions'!E20,'02-Existing Conditions'!H20="*",'02-Existing Conditions'!G20,'02-Existing Conditions'!J20="*",'02-Existing Conditions'!I20,'02-Existing Conditions'!L20="*",'02-Existing Conditions'!K20,'02-Existing Conditions'!N20="*",'02-Existing Conditions'!M20,'02-Existing Conditions'!P20="*",'02-Existing Conditions'!O20,'02-Existing Conditions'!R20="*",'02-Existing Conditions'!Q20,'02-Existing Conditions'!T20="*",'02-Existing Conditions'!S20,'02-Existing Conditions'!V20="*",'02-Existing Conditions'!U20),"")} -> 0 | H27: =G27/'Project Data'!$D$22 -> #VALUE!
A28: ='02-Existing Conditions'!A21 -> 1 | B28: ='02-Existing Conditions'!B21 -> 02 21 00 Surveys | D28: {=_xlfn.IFNA(_xlfn.IFS('02-Existing Conditions'!D21="*",'02-Existing Conditions'!C21,'02-Existing Conditions'!F21="*",'02-Existing Conditions'!E21,'02-Existing Conditions'!H21="*",'02-Existing Conditions'!G21,'02-Existing Conditions'!J21="*",'02-Existing Conditions'!I21,'02-Existing Conditions'!L21="*",'02-Existing Conditions'!K21,'02-Existing Conditions'!N21="*",'02-Existing Conditions'!M21,'02-Existing Conditions'!P21="*",'02-Existing Conditions'!O21,'02-Existing Conditions'!R21="*",'02-Existing Conditions'!Q21,'02-Existing Conditions'!T21="*",'02-Existing Conditions'!S21),"")} -> 30000 | E28: =D28/'Project Data'!$D$22 -> 0.33522924 | F28: 30000 | G28: {=_xlfn.IFNA(_xlfn.IFS('02-Existing Conditions'!F21="*",'02-Existing Conditions'!E21,'02-Existing Conditions'!H21="*",'02-Existing Conditions'!G21,'02-Existing Conditions'!J21="*",'02-Existing Conditions'!I21,'02-Existing Conditions'!L21="*",'02-Existing Conditions'!K21,'02-Existing Conditions'!N21="*",'02-Existing Conditions'!M21,'02-Existing Conditions'!P21="*",'02-Existing Conditions'!O21,'02-Existing Conditions'!R21="*",'02-Existing Conditions'!Q21,'02-Existing Conditions'!T21="*",'02-Existing Conditions'!S21,'02-Existing Conditions'!V21="*",'02-Existing Conditions'!U21),"")} -> 30000 | H28: =G28/'Project Data'!$D$22 -> 0.33522924 | K28: Angleright
A29: ='02-Existing Conditions'!A22 -> 1 | B29: ='02-Existing Conditions'!B22 -> 02 21 13 Construction Security Cameras | D29: ='02-Existing Conditions'!E22 -> 29014 | E29: =D29/'Project Data'!$D$22 -> 0.32421137 | F29: 0 | G29: {=_xlfn.IFNA(_xlfn.IFS('02-Existing Conditions'!F22="*",'02-Existing Conditions'!E22,'02-Existing Conditions'!H22="*",'02-Existing Conditions'!G22,'02-Existing Conditions'!J22="*",'02-Existing Conditions'!I22,'02-Existing Conditions'!L22="*",'02-Existing Conditions'!K22,'02-Existing Conditions'!N22="*",'02-Existing Conditions'!M22,'02-Existing Conditions'!P22="*",'02-Existing Conditions'!O22,'02-Existing Conditions'!R22="*",'02-Existing Conditions'!Q22,'02-Existing Conditions'!T22="*",'02-Existing Conditions'!S22,'02-Existing Conditions'!V22="*",'02-Existing Conditions'!U22),"")} -> 0 | H29: =G29/'Project Data'!$D$22 -> #VALUE! | K29: Stallion
A30: ='02-Existing Conditions'!A23 -> 0 | B30: ='02-Existing Conditions'!B23 -> 02 21 13.13 Boundary and Survey Markers | D30: {=_xlfn.IFNA(_xlfn.IFS('02-Existing Conditions'!D23="*",'02-Existing Conditions'!C23,'02-Existing Conditions'!F23="*",'02-Existing Conditions'!E23,'02-Existing Conditions'!H23="*",'02-Existing Conditions'!G23,'02-Existing Conditions'!J23="*",'02-Existing Conditions'!I23,'02-Existing Conditions'!L23="*",'02-Existing Conditions'!K23,'02-Existing Conditions'!N23="*",'02-Existing Conditions'!M23,'02-Existing Conditions'!P23="*",'02-Existing Conditions'!O23,'02-Existing Conditions'!R23="*",'02-Existing Conditions'!Q23,'02-Existing Conditions'!T23="*",'02-Existing Conditions'!S23),"")} -> 0 | E30: =D30/'Project Data'!$D$22 -> 0 | F30: 0 | G30: {=_xlfn.IFNA(_xlfn.IFS('02-Existing Conditions'!F23="*",'02-Existing Conditions'!E23,'02-Existing Conditions'!H23="*",'02-Existing Conditions'!G23,'02-Existing Conditions'!J23="*",'02-Existing Conditions'!I23,'02-Existing Conditions'!L23="*",'02-Existing Conditions'!K23,'02-Existing Conditions'!N23="*",'02-Existing Conditions'!M23,'02-Existing Conditions'!P23="*",'02-Existing Conditions'!O23,'02-Existing Conditions'!R23="*",'02-Existing Conditions'!Q23,'02-Existing Conditions'!T23="*",'02-Existing Conditions'!S23,'02-Existing Conditions'!V23="*",'02-Existing Conditions'!U23),"")} -> 0 | H30: =G30/'Project Data'!$D$22 -> #VALUE!
A31: ='02-Existing Conditions'!A24 -> 0 | B31: ='02-Existing Conditions'!B24 -> 02 22 00 Existing Conditions Assessment | D31: {=_xlfn.IFNA(_xlfn.IFS('02-Existing Conditions'!D24="*",'02-Existing Conditions'!C24,'02-Existing Conditions'!F24="*",'02-Existing Conditions'!E24,'02-Existing Conditions'!H24="*",'02-Existing Conditions'!G24,'02-Existing Conditions'!J24="*",'02-Existing Conditions'!I24,'02-Existing Conditions'!L24="*",'02-Existing Conditions'!K24,'02-Existing Conditions'!N24="*",'02-Existing Conditions'!M24,'02-Existing Conditions'!P24="*",'02-Existing Conditions'!O24,'02-Existing Conditions'!R24="*",'02-Existing Conditions'!Q24,'02-Existing Conditions'!T24="*",'02-Existing Conditions'!S24),"")} -> 0 | E31: =D31/'Project Data'!$D$22 -> 0 | F31: 0 | G31: {=_xlfn.IFNA(_xlfn.IFS('02-Existing Conditions'!F24="*",'02-Existing Conditions'!E24,'02-Existing Conditions'!H24="*",'02-Existing Conditions'!G24,'02-Existing Conditions'!J24="*",'02-Existing Conditions'!I24,'02-Existing Conditions'!L24="*",'02-Existing Conditions'!K24,'02-Existing Conditions'!N24="*",'02-Existing Conditions'!M24,'02-Existing Conditions'!P24="*",'02-Existing Conditions'!O24,'02-Existing Conditions'!R24="*",'02-Existing Conditions'!Q24,'02-Existing Conditions'!T24="*",'02-Existing Conditions'!S24,'02-Existing Conditions'!V24="*",'02-Existing Conditions'!U24),"")} -> 0 | H31: =G31/'Project Data'!$D$22 -> #VALUE!
A32: ='02-Existing Conditions'!A25 -> 0 | B32: ='02-Existing Conditions'!B25 -> 02 22 13 Movement and Vibration Assessment | D32: {=_xlfn.IFNA(_xlfn.IFS('02-Existing Conditions'!D25="*",'02-Existing Conditions'!C25,'02-Existing Conditions'!F25="*",'02-Existing Conditions'!E25,'02-Existing Conditions'!H25="*",'02-Existing Conditions'!G25,'02-Existing Conditions'!J25="*",'02-Existing Conditions'!I25,'02-Existing Conditions'!L25="*",'02-Existing Conditions'!K25,'02-Existing Conditions'!N25="*",'02-Existing Conditions'!M25,'02-Existing Conditions'!P25="*",'02-Existing Conditions'!O25,'02-Existing Conditions'!R25="*",'02-Existing Conditions'!Q25,'02-Existing Conditions'!T25="*",'02-Existing Conditions'!S25),"")} -> 0 | E32: =D32/'Project Data'!$D$22 -> 0 | F32: 0 | G32: {=_xlfn.IFNA(_xlfn.IFS('02-Existing Conditions'!F25="*",'02-Existing Conditions'!E25,'02-Existing Conditions'!H25="*",'02-Existing Conditions'!G25,'02-Existing Conditions'!J25="*",'02-Existing Conditions'!I25,'02-Existing Conditions'!L25="*",'02-Existing Conditions'!K25,'02-Existing Conditions'!N25="*",'02-Existing Conditions'!M25,'02-Existing Conditions'!P25="*",'02-Existing Conditions'!O25,'02-Existing Conditions'!R25="*",'02-Existing Conditions'!Q25,'02-Existing Conditions'!T25="*",'02-Existing Conditions'!S25,'02-Existing Conditions'!V25="*",'02-Existing Conditions'!U25),"")} -> 0 | H32: =G32/'Project Data'!$D$22 -> #VALUE!
A33: ='02-Existing Conditions'!A26 -> 0 | B33: ='02-Existing Conditions'!B26 -> 02 22 16 Acoustic Assessment | D33: {=_xlfn.IFNA(_xlfn.IFS('02-Existing Conditions'!D26="*",'02-Existing Conditions'!C26,'02-Existing Conditions'!F26="*",'02-Existing Conditions'!E26,'02-Existing Conditions'!H26="*",'02-Existing Conditions'!G26,'02-Existing Conditions'!J26="*",'02-Existing Conditions'!I26,'02-Existing Conditions'!L26="*",'02-Existing Conditions'!K26,'02-Existing Conditions'!N26="*",'02-Existing Conditions'!M26,'02-Existing Conditions'!P26="*",'02-Existing Conditions'!O26,'02-Existing Conditions'!R26="*",'02-Existing Conditions'!Q26,'02-Existing Conditions'!T26="*",'02-Existing Conditions'!S26),"")} -> 0 | E33: =D33/'Project Data'!$D$22 -> 0 | F33: 0 | G33: {=_xlfn.IFNA(_xlfn.IFS('02-Existing Conditions'!F26="*",'02-Existing Conditions'!E26,'02-Existing Conditions'!H26="*",'02-Existing Conditions'!G26,'02-Existing Conditions'!J26="*",'02-Existing Conditions'!I26,'02-Existing Conditions'!L26="*",'02-Existing Conditions'!K26,'02-Existing Conditions'!N26="*",'02-Existing Conditions'!M26,'02-Existing Conditions'!P26="*",'02-Existing Conditions'!O26,'02-Existing Conditions'!R26="*",'02-Existing Conditions'!Q26,'02-Existing Conditions'!T26="*",'02-Existing Conditions'!S26,'02-Existing Conditions'!V26="*",'02-Existing Conditions'!U26),"")} -> 0 | H33: =G33/'Project Data'!$D$22 -> #VALUE!
A34: ='02-Existing Conditions'!A27 -> 0 | B34: ='02-Existing Conditions'!B27 -> 02 22 19 Traffic Assessment | D34: {=_xlfn.IFNA(_xlfn.IFS('02-Existing Conditions'!D27="*",'02-Existing Conditions'!C27,'02-Existing Conditions'!F27="*",'02-Existing Conditions'!E27,'02-Existing Conditions'!H27="*",'02-Existing Conditions'!G27,'02-Existing Conditions'!J27="*",'02-Existing Conditions'!I27,'02-Existing Conditions'!L27="*",'02-Existing Conditions'!K27,'02-Existing Conditions'!N27="*",'02-Existing Conditions'!M27,'02-Existing Conditions'!P27="*",'02-Existing Conditions'!O27,'02-Existing Conditions'!R27="*",'02-Existing Conditions'!Q27,'02-Existing Conditions'!T27="*",'02-Existing Conditions'!S27),"")} -> 0 | E34: =D34/'Project Data'!$D$22 -> 0 | F34: 0 | G34: {=_xlfn.IFNA(_xlfn.IFS('02-Existing Conditions'!F27="*",'02-Existing Conditions'!E27,'02-Existing Conditions'!H27="*",'02-Existing Conditions'!G27,'02-Existing Conditions'!J27="*",'02-Existing Conditions'!I27,'02-Existing Conditions'!L27="*",'02-Existing Conditions'!K27,'02-Existing Conditions'!N27="*",'02-Existing Conditions'!M27,'02-Existing Conditions'!P27="*",'02-Existing Conditions'!O27,'02-Existing Conditions'!R27="*",'02-Existing Conditions'!Q27,'02-Existing Conditions'!T27="*",'02-Existing Conditions'!S27,'02-Existing Conditions'!V27="*",'02-Existing Conditions'!U27),"")} -> 0 | H34: =G34/'Project Data'!$D$22 -> #VALUE!
A35: ='02-Existing Conditions'!A28 -> 0 | B35: ='02-Existing Conditions'!B28 -> 02 24 13.13 Air Assessment | D35: {=_xlfn.IFNA(_xlfn.IFS('02-Existing Conditions'!D28="*",'02-Existing Conditions'!C28,'02-Existing Conditions'!F28="*",'02-Existing Conditions'!E28,'02-Existing Conditions'!H28="*",'02-Existing Conditions'!G28,'02-Existing Conditions'!J28="*",'02-Existing Conditions'!I28,'02-Existing Conditions'!L28="*",'02-Existing Conditions'!K28,'02-Existing Conditions'!N28="*",'02-Existing Conditions'!M28,'02-Existing Conditions'!P28="*",'02-Existing Conditions'!O28,'02-Existing Conditions'!R28="*",'02-Existing Conditions'!Q28,'02-Existing Conditions'!T28="*",'02-Existing Conditions'!S28),"")} -> 0 | E35: =D35/'Project Data'!$D$22 -> 0 | F35: 0 | G35: {=_xlfn.IFNA(_xlfn.IFS('02-Existing Conditions'!F28="*",'02-Existing Conditions'!E28,'02-Existing Conditions'!H28="*",'02-Existing Conditions'!G28,'02-Existing Conditions'!J28="*",'02-Existing Conditions'!I28,'02-Existing Conditions'!L28="*",'02-Existing Conditions'!K28,'02-Existing Conditions'!N28="*",'02-Existing Conditions'!M28,'02-Existing Conditions'!P28="*",'02-Existing Conditions'!O28,'02-Existing Conditions'!R28="*",'02-Existing Conditions'!Q28,'02-Existing Conditions'!T28="*",'02-Existing Conditions'!S28,'02-Existing Conditions'!V28="*",'02-Existing Conditions'!U28),"")} -> 0 | H35: =G35/'Project Data'!$D$22 -> #VALUE!
A36: ='02-Existing Conditions'!A29 -> 0 | B36: ='02-Existing Conditions'!B29 -> 02 24 13.43 Water Assessment | D36: {=_xlfn.IFNA(_xlfn.IFS('02-Existing Conditions'!D29="*",'02-Existing Conditions'!C29,'02-Existing Conditions'!F29="*",'02-Existing Conditions'!E29,'02-Existing Conditions'!H29="*",'02-Existing Conditions'!G29,'02-Existing Conditions'!J29="*",'02-Existing Conditions'!I29,'02-Existing Conditions'!L29="*",'02-Existing Conditions'!K29,'02-Existing Conditions'!N29="*",'02-Existing Conditions'!M29,'02-Existing Conditions'!P29="*",'02-Existing Conditions'!O29,'02-Existing Conditions'!R29="*",'02-Existing Conditions'!Q29,'02-Existing Conditions'!T29="*",'02-Existing Conditions'!S29),"")} -> 0 | E36: =D36/'Project Data'!$D$22 -> 0 | F36: 0 | G36: {=_xlfn.IFNA(_xlfn.IFS('02-Existing Conditions'!F29="*",'02-Existing Conditions'!E29,'02-Existing Conditions'!H29="*",'02-Existing Conditions'!G29,'02-Existing Conditions'!J29="*",'02-Existing Conditions'!I29,'02-Existing Conditions'!L29="*",'02-Existing Conditions'!K29,'02-Existing Conditions'!N29="*",'02-Existing Conditions'!M29,'02-Existing Conditions'!P29="*",'02-Existing Conditions'!O29,'02-Existing Conditions'!R29="*",'02-Existing Conditions'!Q29,'02-Existing Conditions'!T29="*",'02-Existing Conditions'!S29,'02-Existing Conditions'!V29="*",'02-Existing Conditions'!U29),"")} -> 0 | H36: =G36/'Project Data'!$D$22 -> #VALUE!
A37: ='02-Existing Conditions'!A30 -> 0 | B37: ='02-Existing Conditions'!B30 -> 02 24 13.73 Land Assessment | D37: {=_xlfn.IFNA(_xlfn.IFS('02-Existing Conditions'!D30="*",'02-Existing Conditions'!C30,'02-Existing Conditions'!F30="*",'02-Existing Conditions'!E30,'02-Existing Conditions'!H30="*",'02-Existing Conditions'!G30,'02-Existing Conditions'!J30="*",'02-Existing Conditions'!I30,'02-Existing Conditions'!L30="*",'02-Existing Conditions'!K30,'02-Existing Conditions'!N30="*",'02-Existing Conditions'!M30,'02-Existing Conditions'!P30="*",'02-Existing Conditions'!O30,'02-Existing Conditions'!R30="*",'02-Existing Conditions'!Q30,'02-Existing Conditions'!T30="*",'02-Existing Conditions'!S30),"")} -> 0 | E37: =D37/'Project Data'!$D$22 -> 0 | F37: 0 | G37: {=_xlfn.IFNA(_xlfn.IFS('02-Existing Conditions'!F30="*",'02-Existing Conditions'!E30,'02-Existing Conditions'!H30="*",'02-Existing Conditions'!G30,'02-Existing Conditions'!J30="*",'02-Existing Conditions'!I30,'02-Existing Conditions'!L30="*",'02-Existing Conditions'!K30,'02-Existing Conditions'!N30="*",'02-Existing Conditions'!M30,'02-Existing Conditions'!P30="*",'02-Existing Conditions'!O30,'02-Existing Conditions'!R30="*",'02-Existing Conditions'!Q30,'02-Existing Conditions'!T30="*",'02-Existing Conditions'!S30,'02-Existing Conditions'!V30="*",'02-Existing Conditions'!U30),"")} -> 0 | H37: =G37/'Project Data'!$D$22 -> #VALUE!
A38: ='02-Existing Conditions'!A31 -> 0 | B38: ='02-Existing Conditions'!B31 -> 02 24 23 Chemical Sampling and Analysis of Soils | D38: {=_xlfn.IFNA(_xlfn.IFS('02-Existing Conditions'!D31="*",'02-Existing Conditions'!C31,'02-Existing Conditions'!F31="*",'02-Existing Conditions'!E31,'02-Existing Conditions'!H31="*",'02-Existing Conditions'!G31,'02-Existing Conditions'!J31="*",'02-Existing Conditions'!I31,'02-Existing Conditions'!L31="*",'02-Existing Conditions'!K31,'02-Existing Conditions'!N31="*",'02-Existing Conditions'!M31,'02-Existing Conditions'!P31="*",'02-Existing Conditions'!O31,'02-Existing Conditions'!R31="*",'02-Existing Conditions'!Q31,'02-Existing Conditions'!T31="*",'02-Existing Conditions'!S31),"")} -> 0 | E38: =D38/'Project Data'!$D$22 -> 0 | F38: 0 | G38: {=_xlfn.IFNA(_xlfn.IFS('02-Existing Conditions'!F31="*",'02-Existing Conditions'!E31,'02-Existing Conditions'!H31="*",'02-Existing Conditions'!G31,'02-Existing Conditions'!J31="*",'02-Existing Conditions'!I31,'02-Existing Conditions'!L31="*",'02-Existing Conditions'!K31,'02-Existing Conditions'!N31="*",'02-Existing Conditions'!M31,'02-Existing Conditions'!P31="*",'02-Existing Conditions'!O31,'02-Existing Conditions'!R31="*",'02-Existing Conditions'!Q31,'02-Existing Conditions'!T31="*",'02-Existing Conditions'!S31,'02-Existing Conditions'!V31="*",'02-Existing Conditions'!U31),"")} -> 0 | H38: =G38/'Project Data'!$D$22 -> #VALUE!
A39: ='02-Existing Conditions'!A32 -> 0 | B39: ='02-Existing Conditions'!B32 -> 02 25 00 Existing Material Assessment | D39: {=_xlfn.IFNA(_xlfn.IFS('02-Existing Conditions'!D32="*",'02-Existing Conditions'!C32,'02-Existing Conditions'!F32="*",'02-Existing Conditions'!E32,'02-Existing Conditions'!H32="*",'02-Existing Conditions'!G32,'02-Existing Conditions'!J32="*",'02-Existing Conditions'!I32,'02-Existing Conditions'!L32="*",'02-Existing Conditions'!K32,'02-Existing Conditions'!N32="*",'02-Existing Conditions'!M32,'02-Existing Conditions'!P32="*",'02-Existing Conditions'!O32,'02-Existing Conditions'!R32="*",'02-Existing Conditions'!Q32,'02-Existing Conditions'!T32="*",'02-Existing Conditions'!S32),"")} -> 0 | E39: =D39/'Project Data'!$D$22 -> 0 | F39: 0 | G39: {=_xlfn.IFNA(_xlfn.IFS('02-Existing Conditions'!F32="*",'02-Existing Conditions'!E32,'02-Existing Conditions'!H32="*",'02-Existing Conditions'!G32,'02-Existing Conditions'!J32="*",'02-Existing Conditions'!I32,'02-Existing Conditions'!L32="*",'02-Existing Conditions'!K32,'02-Existing Conditions'!N32="*",'02-Existing Conditions'!M32,'02-Existing Conditions'!P32="*",'02-Existing Conditions'!O32,'02-Existing Conditions'!R32="*",'02-Existing Conditions'!Q32,'02-Existing Conditions'!T32="*",'02-Existing Conditions'!S32,'02-Existing Conditions'!V32="*",'02-Existing Conditions'!U32),"")} -> 0 | H39: =G39/'Project Data'!$D$22 -> #VALUE!
A40: ='02-Existing Conditions'!A33 -> 0 | B40: ='02-Existing Conditions'!B33 -> 02 26 00 Hazardous Material Assessment | D40: {=_xlfn.IFNA(_xlfn.IFS('02-Existing Conditions'!D33="*",'02-Existing Conditions'!C33,'02-Existing Conditions'!F33="*",'02-Existing Conditions'!E33,'02-Existing Conditions'!H33="*",'02-Existing Conditions'!G33,'02-Existing Conditions'!J33="*",'02-Existing Conditions'!I33,'02-Existing Conditions'!L33="*",'02-Existing Conditions'!K33,'02-Existing Conditions'!N33="*",'02-Existing Conditions'!M33,'02-Existing Conditions'!P33="*",'02-Existing Conditions'!O33,'02-Existing Conditions'!R33="*",'02-Existing Conditions'!Q33,'02-Existing Conditions'!T33="*",'02-Existing Conditions'!S33),"")} -> 0 | E40: =D40/'Project Data'!$D$22 -> 0 | F40: 0 | G40: {=_xlfn.IFNA(_xlfn.IFS('02-Existing Conditions'!F33="*",'02-Existing Conditions'!E33,'02-Existing Conditions'!H33="*",'02-Existing Conditions'!G33,'02-Existing Conditions'!J33="*",'02-Existing Conditions'!I33,'02-Existing Conditions'!L33="*",'02-Existing Conditions'!K33,'02-Existing Conditions'!N33="*",'02-Existing Conditions'!M33,'02-Existing Conditions'!P33="*",'02-Existing Conditions'!O33,'02-Existing Conditions'!R33="*",'02-Existing Conditions'!Q33,'02-Existing Conditions'!T33="*",'02-Existing Conditions'!S33,'02-Existing Conditions'!V33="*",'02-Existing Conditions'!U33),"")} -> 0 | H40: =G40/'Project Data'!$D$22 -> #VALUE!
A41: ='02-Existing Conditions'!A34 -> 0 | B41: ='02-Existing Conditions'!B34 -> 02 26 23 Asbestos Assessment | D41: {=_xlfn.IFNA(_xlfn.IFS('02-Existing Conditions'!D34="*",'02-Existing Conditions'!C34,'02-Existing Conditions'!F34="*",'02-Existing Conditions'!E34,'02-Existing Conditions'!H34="*",'02-Existing Conditions'!G34,'02-Existing Conditions'!J34="*",'02-Existing Conditions'!I34,'02-Existing Conditions'!L34="*",'02-Existing Conditions'!K34,'02-Existing Conditions'!N34="*",'02-Existing Conditions'!M34,'02-Existing Conditions'!P34="*",'02-Existing Conditions'!O34,'02-Existing Conditions'!R34="*",'02-Existing Conditions'!Q34,'02-Existing Conditions'!T34="*",'02-Existing Conditions'!S34),"")} -> 0 | E41: =D41/'Project Data'!$D$22 -> 0 | F41: 0 | G41: {=_xlfn.IFNA(_xlfn.IFS('02-Existing Conditions'!F34="*",'02-Existing Conditions'!E34,'02-Existing Conditions'!H34="*",'02-Existing Conditions'!G34,'02-Existing Conditions'!J34="*",'02-Existing Conditions'!I34,'02-Existing Conditions'!L34="*",'02-Existing Conditions'!K34,'02-Existing Conditions'!N34="*",'02-Existing Conditions'!M34,'02-Existing Conditions'!P34="*",'02-Existing Conditions'!O34,'02-Existing Conditions'!R34="*",'02-Existing Conditions'!Q34,'02-Existing Conditions'!T34="*",'02-Existing Conditions'!S34,'02-Existing Conditions'!V34="*",'02-Existing Conditions'!U34),"")} -> 0 | H41: =G41/'Project Data'!$D$22 -> #VALUE!
A42: ='02-Existing Conditions'!A35 -> 0 | B42: ='02-Existing Conditions'!B35 -> 02 26 26 Lead Assessment | D42: {=_xlfn.IFNA(_xlfn.IFS('02-Existing Conditions'!D35="*",'02-Existing Conditions'!C35,'02-Existing Conditions'!F35="*",'02-Existing Conditions'!E35,'02-Existing Conditions'!H35="*",'02-Existing Conditions'!G35,'02-Existing Conditions'!J35="*",'02-Existing Conditions'!I35,'02-Existing Conditions'!L35="*",'02-Existing Conditions'!K35,'02-Existing Conditions'!N35="*",'02-Existing Conditions'!M35,'02-Existing Conditions'!P35="*",'02-Existing Conditions'!O35,'02-Existing Conditions'!R35="*",'02-Existing Conditions'!Q35,'02-Existing Conditions'!T35="*",'02-Existing Conditions'!S35),"")} -> 0 | E42: =D42/'Project Data'!$D$22 -> 0 | F42: 0 | G42: {=_xlfn.IFNA(_xlfn.IFS('02-Existing Conditions'!F35="*",'02-Existing Conditions'!E35,'02-Existing Conditions'!H35="*",'02-Existing Conditions'!G35,'02-Existing Conditions'!J35="*",'02-Existing Conditions'!I35,'02-Existing Conditions'!L35="*",'02-Existing Conditions'!K35,'02-Existing Conditions'!N35="*",'02-Existing Conditions'!M35,'02-Existing Conditions'!P35="*",'02-Existing Conditions'!O35,'02-Existing Conditions'!R35="*",'02-Existing Conditions'!Q35,'02-Existing Conditions'!T35="*",'02-Existing Conditions'!S35,'02-Existing Conditions'!V35="*",'02-Existing Conditions'!U35),"")} -> 0 | H42: =G42/'Project Data'!$D$22 -> #VALUE!
A43: ='02-Existing Conditions'!A36 -> 1 | B43: ='02-Existing Conditions'!B36 -> 02 26 33.13 Final Cleaning | D43: ='02-Existing Conditions'!E36 -> 41700 | E43: =D43/'Project Data'!$D$22 -> 0.46596864 | F43: 0 | G43: {=_xlfn.IFNA(_xlfn.IFS('02-Existing Conditions'!F36="*",'02-Existing Conditions'!E36,'02-Existing Conditions'!H36="*",'02-Existing Conditions'!G36,'02-Existing Conditions'!J36="*",'02-Existing Conditions'!I36,'02-Existing Conditions'!L36="*",'02-Existing Conditions'!K36,'02-Existing Conditions'!N36="*",'02-Existing Conditions'!M36,'02-Existing Conditions'!P36="*",'02-Existing Conditions'!O36,'02-Existing Conditions'!R36="*",'02-Existing Conditions'!Q36,'02-Existing Conditions'!T36="*",'02-Existing Conditions'!S36,'02-Existing Conditions'!V36="*",'02-Existing Conditions'!U36),"")} -> 0 | H43: =G43/'Project Data'!$D$22 -> #VALUE! | K43: Florida Construction Cleanup
A44: ='02-Existing Conditions'!A37 -> 0 | B44: ='02-Existing Conditions'!B37 -> 02 26 36 Hazardous Waste Drum Assessment | D44: {=_xlfn.IFNA(_xlfn.IFS('02-Existing Conditions'!D37="*",'02-Existing Conditions'!C37,'02-Existing Conditions'!F37="*",'02-Existing Conditions'!E37,'02-Existing Conditions'!H37="*",'02-Existing Conditions'!G37,'02-Existing Conditions'!J37="*",'02-Existing Conditions'!I37,'02-Existing Conditions'!L37="*",'02-Existing Conditions'!K37,'02-Existing Conditions'!N37="*",'02-Existing Conditions'!M37,'02-Existing Conditions'!P37="*",'02-Existing Conditions'!O37,'02-Existing Conditions'!R37="*",'02-Existing Conditions'!Q37,'02-Existing Conditions'!T37="*",'02-Existing Conditions'!S37),"")} -> 0 | E44: =D44/'Project Data'!$D$22 -> 0 | F44: 0 | G44: {=_xlfn.IFNA(_xlfn.IFS('02-Existing Conditions'!F37="*",'02-Existing Conditions'!E37,'02-Existing Conditions'!H37="*",'02-Existing Conditions'!G37,'02-Existing Conditions'!J37="*",'02-Existing Conditions'!I37,'02-Existing Conditions'!L37="*",'02-Existing Conditions'!K37,'02-Existing Conditions'!N37="*",'02-Existing Conditions'!M37,'02-Existing Conditions'!P37="*",'02-Existing Conditions'!O37,'02-Existing Conditions'!R37="*",'02-Existing Conditions'!Q37,'02-Existing Conditions'!T37="*",'02-Existing Conditions'!S37,'02-Existing Conditions'!V37="*",'02-Existing Conditions'!U37),"")} -> 0 | H44: =G44/'Project Data'!$D$22 -> #VALUE!
A45: ='02-Existing Conditions'!A38 -> 0 | B45: ='02-Existing Conditions'!B38 -> 02 30 00 Subsurface Investigation | D45: {=_xlfn.IFNA(_xlfn.IFS('02-Existing Conditions'!D38="*",'02-Existing Conditions'!C38,'02-Existing Conditions'!F38="*",'02-Existing Conditions'!E38,'02-Existing Conditions'!H38="*",'02-Existing Conditions'!G38,'02-Existing Conditions'!J38="*",'02-Existing Conditions'!I38,'02-Existing Conditions'!L38="*",'02-Existing Conditions'!K38,'02-Existing Conditions'!N38="*",'02-Existing Conditions'!M38,'02-Existing Conditions'!P38="*",'02-Existing Conditions'!O38,'02-Existing Conditions'!R38="*",'02-Existing Conditions'!Q38,'02-Existing Conditions'!T38="*",'02-Existing Conditions'!S38),"")} -> 0 | E45: =D45/'Project Data'!$D$22 -> 0 | F45: 0 | G45: {=_xlfn.IFNA(_xlfn.IFS('02-Existing Conditions'!F38="*",'02-Existing Conditions'!E38,'02-Existing Conditions'!H38="*",'02-Existing Conditions'!G38,'02-Existing Conditions'!J38="*",'02-Existing Conditions'!I38,'02-Existing Conditions'!L38="*",'02-Existing Conditions'!K38,'02-Existing Conditions'!N38="*",'02-Existing Conditions'!M38,'02-Existing Conditions'!P38="*",'02-Existing Conditions'!O38,'02-Existing Conditions'!R38="*",'02-Existing Conditions'!Q38,'02-Existing Conditions'!T38="*",'02-Existing Conditions'!S38,'02-Existing Conditions'!V38="*",'02-Existing Conditions'!U38),"")} -> 0 | H45: =G45/'Project Data'!$D$22 -> #VALUE!
A46: ='02-Existing Conditions'!A39 -> 0 | B46: ='02-Existing Conditions'!B39 -> 02 32 13 Subsurface Drilling and Sampling | D46: {=_xlfn.IFNA(_xlfn.IFS('02-Existing Conditions'!D39="*",'02-Existing Conditions'!C39,'02-Existing Conditions'!F39="*",'02-Existing Conditions'!E39,'02-Existing Conditions'!H39="*",'02-Existing Conditions'!G39,'02-Existing Conditions'!J39="*",'02-Existing Conditions'!I39,'02-Existing Conditions'!L39="*",'02-Existing Conditions'!K39,'02-Existing Conditions'!N39="*",'02-Existing Conditions'!M39,'02-Existing Conditions'!P39="*",'02-Existing Conditions'!O39,'02-Existing Conditions'!R39="*",'02-Existing Conditions'!Q39,'02-Existing Conditions'!T39="*",'02-Existing Conditions'!S39),"")} -> 0 | E46: =D46/'Project Data'!$D$22 -> 0 | F46: 0 | G46: {=_xlfn.IFNA(_xlfn.IFS('02-Existing Conditions'!F39="*",'02-Existing Conditions'!E39,'02-Existing Conditions'!H39="*",'02-Existing Conditions'!G39,'02-Existing Conditions'!J39="*",'02-Existing Conditions'!I39,'02-Existing Conditions'!L39="*",'02-Existing Conditions'!K39,'02-Existing Conditions'!N39="*",'02-Existing Conditions'!M39,'02-Existing Conditions'!P39="*",'02-Existing Conditions'!O39,'02-Existing Conditions'!R39="*",'02-Existing Conditions'!Q39,'02-Existing Conditions'!T39="*",'02-Existing Conditions'!S39,'02-Existing Conditions'!V39="*",'02-Existing Conditions'!U39),"")} -> 0 | H46: =G46/'Project Data'!$D$22 -> #VALUE!
A47: ='02-Existing Conditions'!A40 -> 1 | B47: ='02-Existing Conditions'!B40 -> 02 32 16 Material Testing & Threshold Inspections | D47: ='02-Existing Conditions'!E40 -> 21238 | E47: =D47/'Project Data'!$D$22 -> 0.23731995 | F47: 0 | G47: {=_xlfn.IFNA(_xlfn.IFS('02-Existing Conditions'!F40="*",'02-Existing Conditions'!E40,'02-Existing Conditions'!H40="*",'02-Existing Conditions'!G40,'02-Existing Conditions'!J40="*",'02-Existing Conditions'!I40,'02-Existing Conditions'!L40="*",'02-Existing Conditions'!K40,'02-Existing Conditions'!N40="*",'02-Existing Conditions'!M40,'02-Existing Conditions'!P40="*",'02-Existing Conditions'!O40,'02-Existing Conditions'!R40="*",'02-Existing Conditions'!Q40,'02-Existing Conditions'!T40="*",'02-Existing Conditions'!S40,'02-Existing Conditions'!V40="*",'02-Existing Conditions'!U40),"")} -> 0 | H47: =G47/'Project Data'!$D$22 -> #VALUE! | K47: Pacson
A48: ='02-Existing Conditions'!A41 -> 0 | B48: ='02-Existing Conditions'!B41 -> 02 32 19 Exploratory Excavations | D48: {=_xlfn.IFNA(_xlfn.IFS('02-Existing Conditions'!D41="*",'02-Existing Conditions'!C41,'02-Existing Conditions'!F41="*",'02-Existing Conditions'!E41,'02-Existing Conditions'!H41="*",'02-Existing Conditions'!G41,'02-Existing Conditions'!J41="*",'02-Existing Conditions'!I41,'02-Existing Conditions'!L41="*",'02-Existing Conditions'!K41,'02-Existing Conditions'!N41="*",'02-Existing Conditions'!M41,'02-Existing Conditions'!P41="*",'02-Existing Conditions'!O41,'02-Existing Conditions'!R41="*",'02-Existing Conditions'!Q41,'02-Existing Conditions'!T41="*",'02-Existing Conditions'!S41),"")} -> 0 | E48: =D48/'Project Data'!$D$22 -> 0 | F48: 0 | G48: {=_xlfn.IFNA(_xlfn.IFS('02-Existing Conditions'!F41="*",'02-Existing Conditions'!E41,'02-Existing Conditions'!H41="*",'02-Existing Conditions'!G41,'02-Existing Conditions'!J41="*",'02-Existing Conditions'!I41,'02-Existing Conditions'!L41="*",'02-Existing Conditions'!K41,'02-Existing Conditions'!N41="*",'02-Existing Conditions'!M41,'02-Existing Conditions'!P41="*",'02-Existing Conditions'!O41,'02-Existing Conditions'!R41="*",'02-Existing Conditions'!Q41,'02-Existing Conditions'!T41="*",'02-Existing Conditions'!S41,'02-Existing Conditions'!V41="*",'02-Existing Conditions'!U41),"")} -> 0 | H48: =G48/'Project Data'!$D$22 -> #VALUE!
A49: 1 | B49: Div. 02 42 - Demolition | D49: =SUM(D51:D54) -> 503586 | E49: =D49/'Project Data'!$D$22 -> 5.6272251 | F49: 503586 | G49: {=_xlfn.IFNA(_xlfn.IFS('02-41-Demolition'!F9="*",'02-41-Demolition'!E9,'02-41-Demolition'!H9="*",'02-41-Demolition'!G9,'02-41-Demolition'!J9="*",'02-41-Demolition'!I9,'02-41-Demolition'!L9="*",'02-41-Demolition'!K9,'02-41-Demolition'!N9="*",'02-41-Demolition'!M9,'02-41-Demolition'!P9="*",'02-41-Demolition'!O9,'02-41-Demolition'!R9="*",'02-41-Demolition'!Q9,'02-41-Demolition'!T9="*",'02-41-Demolition'!S9,'02-41-Demolition'!V9="*",'02-41-Demolition'!U9),"")} -> 503586 | H49: =G49/'Project Data'!$D$22 -> 5.6272251 | J49: =IFERROR(G49-F49, "--") -> 0
A50: ='02-41-Demolition'!A11 -> 0 | B50: ='02-41-Demolition'!B11 -> 02 41 00 Demolition | D50: {=_xlfn.IFNA(_xlfn.IFS('02-41-Demolition'!D11="*",'02-41-Demolition'!C11,'02-41-Demolition'!F11="*",'02-41-Demolition'!E11,'02-41-Demolition'!H11="*",'02-41-Demolition'!G11,'02-41-Demolition'!J11="*",'02-41-Demolition'!I11,'02-41-Demolition'!L11="*",'02-41-Demolition'!K11,'02-41-Demolition'!N11="*",'02-41-Demolition'!M11,'02-41-Demolition'!P11="*",'02-41-Demolition'!O11,'02-41-Demolition'!R11="*",'02-41-Demolition'!Q11,'02-41-Demolition'!T11="*",'02-41-Demolition'!S11),"")} | E50: =D50/'Project Data'!$D$22 -> #VALUE! | G50: {=_xlfn.IFNA(_xlfn.IFS('02-41-Demolition'!F11="*",'02-41-Demolition'!E11,'02-41-Demolition'!H11="*",'02-41-Demolition'!G11,'02-41-Demolition'!J11="*",'02-41-Demolition'!I11,'02-41-Demolition'!L11="*",'02-41-Demolition'!K11,'02-41-Demolition'!N11="*",'02-41-Demolition'!M11,'02-41-Demolition'!P11="*",'02-41-Demolition'!O11,'02-41-Demolition'!R11="*",'02-41-Demolition'!Q11,'02-41-Demolition'!T11="*",'02-41-Demolition'!S11,'02-41-Demolition'!V11="*",'02-41-Demolition'!U11),"")} | H50: =G50/'Project Data'!$D$22 -> #VALUE!
...

Sheet Project Data
A2: Prepared By: | B2: CS
B3: Date: | C3: Rev. | D3: 1 | G3: Alexa Sass: PM/Designer
B4: Josephine Apartments (3rd Ave.) | G4: Sinatra Development LLC
B5: 3rd Avenue | G5: asass@sinatraandcompany.com
G6: 716-345-8673
G8: Cole T. Hatley
G9: VP of Construction Management Ops
G10: Sinatra Development LLC
B11: Project SF Items to be broken-out: | C11: Acres | D11: SF | G11: chatley@sinatraandcompany.com
B12: Site
B13: Site in SF (43,560 SF = 1 Acre) | C13: 9 | D13: =C13*43560 -> 392040 | E13: Notes:
B14: Building Footprint | D14: 20117
B15: Asphalt paving | D15: 25000
B16: Concrete paving Include curb and gutter | D16: 10000
B17: Concrete flat work and sidewalk | D17: 4000
B18: Brick pavers | D18: 5000
B19: Landscaped area (Landscape = Site - Bldg. FP - Pavement - Flatwork - Pavers) | D19: =D13-SUM(D14:D18) -> 327923
B21: Building
B22: Building GSF | D22: 89491
B23: Unit Quanity | D23: 99
B24: # Floors including basement | D24: 4
B25: # elevators | D25: 1
B26: Exterior finishes
B27: Masonry | D27: 6000
B28: Metal pannel | D28: 4500
B29: Siding | D29: 1200
B30: Exteior paint | D30: 1200
B31: Storefront | D31: 2600
B32: Windows | D32: 4000
B33: Finishes (GSF)
C37: %
B38: Contractor Contingency | C38: 0.05
B39: GL/PL Insurance: | C39: 0.012
B40: Performance Bond: | C40: 0
B41: GC Fee: | C41: 0.05
B42: Escalation | C42: 0
E5121: =(E5118+E5119+E5120)*#REF! -> #REF!

Sheet GCGR's
A2: STAFF PLAN
A3: SCHEDULE | C3: YEAR | D3: 2026 | E3: 2026 | F3: 2026 | G3: 2026 | H3: 2026 | I3: 2026 | J3: 2026 | K3: 2026 | L3: 2026 | M3: 2027 | N3: 2027 | O3: 2027 | P3: 2027 | Q3: 2027 | R3: 2027 | S3: 2027 | T3: 2027 | U3: 2027 | V3: 2027 | W3: 2027 | X3: 2027 | Y3: 2028 | Z3: 2028 | AA3: 2028 | AB3: 2028 | AC3: 2028
C4: DURATION | D4: {=_xlfn.IFS($B$10,1)} -> 1 | E4: {=_xlfn.IFS($B$10>D4,D4+1,D4<$B$10,0)} -> 2 | F4: {=_xlfn.IFS($B$10>E4,E4+1,E4<$B$10,0)} -> 3 | G4: {=_xlfn.IFS($B$10>F4,F4+1,F4<$B$10,0)} -> 4 | H4: {=_xlfn.IFS($B$10>G4,G4+1,G4<$B$10,0)} -> 5 | I4: {=_xlfn.IFS($B$10>H4,H4+1,H4<$B$10,0)} -> 6 | J4: {=_xlfn.IFS($B$10>I4,I4+1,I4<$B$10,0)} -> 7 | K4: {=_xlfn.IFS($B$10>J4,J4+1,J4<$B$10,0)} -> 8 | L4: {=_xlfn.IFS($B$10>K4,K4+1,K4<$B$10,0)} -> 9 | ... AC4: {=_xlfn.IFS($B$10>AB4,AB4+1,AB4<$B$10,0)} -> #N/A
C5: MONTH | D5: APR | E5: MAY | F5: JUN | G5: JULY | H5: AUG | I5: SEP | J5: OCT | K5: NOV | L5: DEC | M5: JAN | N5: FEB | O5: MAR | P5: APR | Q5: MAY | R5: JUNE | S5: JULY | T5: AUGUST | U5: SEPTEMBER | V5: OCTOBER | W5: NOVEMBER | X5: DECEMBER | Y5: JANUARY | Z5: FEBRUARY | AA5: MARCH | AB5: APRIL | AC5: MAY
A7: Anticipated Notice to Proceed:
A8: Preconstruction Duration (Months) | B8: NA
A9: Construction Start | B9: 46114
A10: Construction Duration (Months) | B10: =(B12-B9)/30.147 -> 11.941487 | D10: =D4 -> 1 | E10: =E4 -> 2 | F10: =F4 -> 3 | G10: =G4 -> 4 | H10: =H4 -> 5 | I10: =I4 -> 6 | J10: =J4 -> 7 | K10: =K4 -> 8 | ... AC10: =AC4 -> #N/A
A11: Building Enclosed | B11: 46327
A12: Substantial Completion / Cert of Occupancy | B12: 46474
A13: Closeout/Punchlist | B13: 46479
A15: STAFF PLAN | D15: =D5 -> APR | E15: =E5 -> MAY | F15: =F5 -> JUN | G15: =G5 -> JULY | H15: =H5 -> AUG | I15: =I5 -> SEP | J15: =J5 -> OCT | K15: =K5 -> NOV | ... AC15: =AC5 -> MAY | AD15: NOTES | AE15: RATES | AG15: DO NOT ENTER RATES HERE
A16: MANAGEMENT | AE16: MANAGEMENT | AF16: TOTAL HOURS | AG16: RATE / HR. | AH16: RATE/MO. | AI16: TOTAL
A17: Project Executive | B17: N&A | D17: 0 | E17: 0 | F17: 0 | G17: 0 | H17: 0 | I17: 0 | J17: 0 | K17: 0 | L17: 0 | M17: 0 | N17: 0 | O17: 0 | AE17: =A17 -> Project Executive | AF17: =SUM(D17:AC17) -> 0 | AG17: 150 | AI17: =AF17*AG17 -> 0
A18: Senior Project Manager | B18: N&A | D18: =(2080/12)*0.05 -> 8.6666667 | E18: =(2080/12)*0.05 -> 8.6666667 | F18: =(2080/12)*0.05 -> 8.6666667 | G18: =(2080/12)*0.05 -> 8.6666667 | H18: =(2080/12)*0.05 -> 8.6666667 | I18: =(2080/12)*0.05 -> 8.6666667 | J18: =(2080/12)*0.05 -> 8.6666667 | K18: =(2080/12)*0.05 -> 8.6666667 | ... O18: =(2080/12)*0.05 -> 8.6666667 | AE18: =A18 -> Senior Project Manager | AF18: =SUM(D18:AC18) -> 104 | AG18: 150 | AI18: =AF18*AG18 -> 15600
A19: Project Manager | B19: N&A | D19: =(2080/12)*0.2 -> 34.666667 | E19: =(2080/12)*0.2 -> 34.666667 | F19: =(2080/12)*0.2 -> 34.666667 | G19: =(2080/12)*0.2 -> 34.666667 | H19: =(2080/12)*0.2 -> 34.666667 | I19: =(2080/12)*0.2 -> 34.666667 | J19: =(2080/12)*0.2 -> 34.666667 | K19: =(2080/12)*0.2 -> 34.666667 | ... O19: =(2080/12)*0.2 -> 34.666667 | AE19: =A19 -> Project Manager | AF19: =SUM(D19:AC19) -> 416 | AG19: 145 | AI19: =AF19*AG19 -> 60320
A20: Project Engineer | B20: N&A | D20: =(2080/12)*0.15 -> 26 | E20: =(2080/12)*0.15 -> 26 | F20: =(2080/12)*0.15 -> 26 | G20: =(2080/12)*0.15 -> 26 | H20: =(2080/12)*0.15 -> 26 | I20: =(2080/12)*0.15 -> 26 | J20: =(2080/12)*0.15 -> 26 | K20: =(2080/12)*0.15 -> 26 | ... O20: =(2080/12)*0.15 -> 26 | AE20: =A20 -> Project Engineer | AF20: =SUM(D20:AC20) -> 312 | AG20: 115 | AI20: =AF20*AG20 -> 35880
A21: FIELD | AE21: =A21 -> FIELD | AF21: =SUM(D21:AC21) -> 0
A22: Senior Superintendent | B22: N&A | D22: =(2080/12)*0.05 -> 8.6666667 | E22: =(2080/12)*0.05 -> 8.6666667 | F22: =(2080/12)*0.05 -> 8.6666667 | G22: =(2080/12)*0.05 -> 8.6666667 | H22: =(2080/12)*0.05 -> 8.6666667 | I22: =(2080/12)*0.05 -> 8.6666667 | J22: =(2080/12)*0.05 -> 8.6666667 | K22: =(2080/12)*0.05 -> 8.6666667 | ... O22: =(2080/12)*0.05 -> 8.6666667 | AE22: =A22 -> Senior Superintendent | AF22: =SUM(D22:AC22) -> 104 | AG22: 140 | AI22: =AF22*AG22 -> 14560
A23: Superintendent | B23: N&A | D23: =(2080/12)*1 -> 173.33333 | E23: =(2080/12)*1 -> 173.33333 | F23: =(2080/12)*1 -> 173.33333 | G23: =(2080/12)*1 -> 173.33333 | H23: =(2080/12)*1 -> 173.33333 | I23: =(2080/12)*1 -> 173.33333 | J23: =(2080/12)*1 -> 173.33333 | K23: =(2080/12)*1 -> 173.33333 | ... O23: =(2080/12)*1 -> 173.33333 | AE23: =A23 -> Superintendent | AF23: =SUM(D23:AC23) -> 2080 | AG23: 135 | AI23: =AF23*AG23 -> 280800
A24: Assistant Superintendent | B24: N&A | D24: =(2080/12)*1 -> 173.33333 | E24: =(2080/12)*1 -> 173.33333 | F24: =(2080/12)*1 -> 173.33333 | G24: =(2080/12)*1 -> 173.33333 | H24: =(2080/12)*1 -> 173.33333 | I24: =(2080/12)*1 -> 173.33333 | J24: =(2080/12)*1 -> 173.33333 | K24: =(2080/12)*1 -> 173.33333 | ... O24: =(2080/12)*1 -> 173.33333 | AE24: =A24 -> Assistant Superintendent | AF24: =SUM(D24:AC24) -> 2080 | AG24: 110 | AI24: =AF24*AG24 -> 228800
A25: Laborer | B25: N&A | D25: =(2080/12)*0.25 -> 43.333333 | E25: =(2080/12)*0.25 -> 43.333333 | F25: =(2080/12)*0.25 -> 43.333333 | G25: =(2080/12)*0.25 -> 43.333333 | H25: =(2080/12)*0.25 -> 43.333333 | I25: =(2080/12)*0.25 -> 43.333333 | J25: =(2080/12)*0.25 -> 43.333333 | K25: =(2080/12)*0.25 -> 43.333333 | ... O25: =(2080/12)*0.25 -> 43.333333 | AE25: =A25 -> Laborer | AF25: =SUM(D25:AC25) -> 520 | AG25: 90 | AI25: =AF25*AG25 -> 46800
A26: SUPPORT | AE26: =A26 -> SUPPORT | AF26: =SUM(D26:AC26) -> 0
A27: Preconstruction Manager | B27: N&A | AE27: =A27 -> Preconstruction Manager | AF27: =SUM(D27:AC27) -> 0 | AG27: 0
A28: Project Administrative Assistant | B28: N&A | D28: =(2080/12)*0.25 -> 43.333333 | E28: =(2080/12)*0.25 -> 43.333333 | F28: =(2080/12)*0.25 -> 43.333333 | G28: =(2080/12)*0.25 -> 43.333333 | H28: =(2080/12)*0.25 -> 43.333333 | I28: =(2080/12)*0.05 -> 8.6666667 | J28: =(2080/12)*0.05 -> 8.6666667 | K28: =(2080/12)*0.05 -> 8.6666667 | L28: =(2080/12)*0.05 -> 8.6666667 | M28: =(2080/12)*0.25 -> 43.333333 | N28: =(2080/12)*0.25 -> 43.333333 | O28: =(2080/12)*0.25 -> 43.333333 | AE28: =A28 -> Project Administrative Assistant | AF28: =SUM(D28:AC28) -> 381.33333 | AG28: 65 | AI28: =AF28*AG28 -> 24786.667
A29: Project Accounting | B29: N&A | D29: 10 | E29: 10 | F29: 10 | G29: 10 | H29: 10 | I29: 10 | J29: 10 | K29: 10 | L29: 10 | M29: 10 | N29: 10 | O29: 10 | AE29: =A29 -> Project Accounting | AF29: =SUM(D29:AC29) -> 120 | AG29: 65 | AI29: =AF29*AG29 -> 7800
A30: TOTAL STAFFING | D30: =SUM(D17:D29) -> 521.33333 | E30: =SUM(E17:E29) -> 521.33333 | F30: =SUM(F17:F29) -> 521.33333 | G30: =SUM(G17:G29) -> 521.33333 | H30: =SUM(H17:H29) -> 521.33333 | I30: =SUM(I17:I29) -> 486.66667 | J30: =SUM(J17:J29) -> 486.66667 | K30: =SUM(K17:K29) -> 486.66667 | ... AC30: =SUM(AC17:AC29) -> 0 | AE30: TOTAL HOURS / MANPOWER COSTS | AF30: =SUM(AF17:AF29) -> 6117.3333 | AG30: TOTAL w/ benefits | AI30: =SUM(AI17:AI29) -> 715346.67
A31: GENERAL CONDITIONS & REIMBURSABLES | AD31: NOTES
D33: =D5 -> APR | E33: =E5 -> MAY | F33: =F5 -> JUN | G33: =G5 -> JULY | H33: =H5 -> AUG | I33: =I5 -> SEP | J33: =J5 -> OCT | K33: =K5 -> NOV | ... AC33: =AC5 -> MAY | AE33: EXPENSES
A34: Safety Director | B34: LS | C34: $400 per Audit | D34: 0 | E34: 0 | F34: 0 | G34: 0 | H34: 0 | I34: 0 | J34: 0 | O34: 0 | AE34: =A34 -> Safety Director | AF34: =SUM(D34:AC34) -> 0
A35: Site cleaning | B35: months | D35: 0 | E35: 0 | F35: 0 | G35: 0 | H35: 0 | I35: 0 | J35: 0 | O35: 0 | AE35: =A35 -> Site cleaning | AF35: =SUM(D35:AC35) -> 0
A36: Printer & Network | B36: months | D36: 200 | E36: 200 | F36: 200 | G36: 200 | H36: 200 | I36: 200 | J36: 200 | K36: 200 | L36: 200 | M36: 200 | N36: 200 | O36: 200 | AE36: =A36 -> Printer & Network | AF36: =SUM(D36:AC36) -> 2400
A37: Computers | B37: months | D37: 125 | E37: 125 | F37: 125 | G37: 125 | H37: 125 | I37: 125 | J37: 125 | K37: 125 | L37: 125 | M37: 125 | N37: 125 | O37: 125 | AE37: =A37 -> Computers | AF37: =SUM(D37:AC37) -> 1500
A38: Copying & Reproduction | B38: months | D38: 250 | E38: 250 | F38: 250 | G38: 250 | H38: 250 | I38: 100 | J38: 100 | K38: 100 | L38: 100 | M38: 100 | N38: 100 | O38: 100 | AE38: =A38 -> Copying & Reproduction | AF38: =SUM(D38:AC38) -> 1950
A39: Dumpsters | B39: months | F39: 1000 | G39: 1000 | H39: 1000 | I39: 1000 | J39: 1000 | K39: 2000 | L39: 2000 | M39: 2000 | N39: 1000 | O39: 1000 | AE39: =A39 -> Dumpsters | AF39: =SUM(D39:AC39) -> 13000
A40: Estimating Services | B40: LS | AE40: =A40 -> Estimating Services | AF40: =SUM(D40:AC40) -> 0
A41: Final Cleaning | B41: LS | N41: 35412 | O41: 35412 | AE41: =A41 -> Final Cleaning | AF41: =SUM(D41:AC41) -> 70824
A42: Miscellaneous General Expense | B42: months | AE42: =A42 -> Miscellaneous General Expense | AF42: =SUM(D42:AC42) -> 0
A43: Office Equipment & Supplies | B43: months | D43: 100 | E43: 100 | F43: 100 | G43: 100 | H43: 100 | I43: 100 | J43: 100 | K43: 100 | L43: 100 | M43: 100 | N43: 100 | O43: 100 | AE43: =A43 -> Office Equipment & Supplies | AF43: =SUM(D43:AC43) -> 1200
A44: Project Signage (General Contractor) | B44: LS | D44: 500 | E44: 500 | N44: 500 | O44: 500 | AE44: =A44 -> Project Signage (General Contractor) | AF44: =SUM(D44:AC44) -> 2000
...

Sheet Historical
E7: DIV | F7: Value | G7: Trade | H7: Subcontractor | I7: Description
E8: 5 | F8: 6380 | G8: Railings | H8: KN Edwards | I8: picket railing

Sheet 02-Existing Conditions
C1: Quantity | D1: Unit Pricing | E1: Nicholas Estimate | F1: *= Use | G1: Final Cleaning | H1: Survey | I1: Final Cleaning | J1: Final Cleaning | K1: Final Cleaning | L1: Final Cleaning | M1: Final Cleaning | N1: Inspections: Do we need this ? | O1: Final Cleaning | P1: Final Cleaning | Q1: Testing | R1: Testing | S1: Testing | T1: Testing | U1: Final Cleaning | V1: *= Use | W1: Survey | X1: Final Cleaning | Z1: Testing | AA1: Surveying | AB1: Final Cleaning | AC1: Final Cleaning | AD1: Surveying | AE1: Testing | AF1: Cleaning | AG1: Cleaning | AH1: Cleaning
A2: Prepared By: | G2: Peak Cleaners | H2: On Point | I2: Britlena Cleaning Services | J2: Florida Construction Cleanup | K2: Florida Construction Cleanup | L2: Rosies | M2: Peak Cleaners | N2: Strategic Engineering | O2: Proline Cleaners | P2: Kirocz Cleaning Services | Q2: Intertek | R2: Deatrick Engineering | S2: Team UES | T2: Pacson | U2: Greta Cleaning Services | W2: Ferguson Land Surveyors | X2: AMAH | Z2: Terracon | AA2: Angleright | AB2: Avi & Park Solutions | AC2: Florida Coast | AD2: American Layout & Land Surveying | AE2: Pacifica | AF2: Polished Perfection Cleaning | AG2: BrightSite Cleaning | AH2: Final Touch
